Workbook

Sheet Respuestas
A1: 1 | B1: =+A1+1 -> 2 | C1: =+B1+1 -> 3 | D1: =+C1+1 -> 4 | E1: =+D1+1 -> 5 | F1: =+E1+1 -> 6 | G1: =+F1+1 -> 7 | H1: =+G1+1 -> 8 | I1: =+H1+1 -> 9 | ... HO1: =+HN1+1 -> 223
A2: ID | B2: Marca temporal | C2: 1. NOMBRE: | D2: 2. FECHA DE NACIMIENTO | E2: 3. Departamento en el que labora: | F2: 4. Puesto: | G2: 5. Estado Civil: | H2: 6. Sexo: | I2: 7. Estudios realizados: | J2: 8. ¿Cuál es su categoría dentro de la empresa? | K2: 9. ¿Antigüedad en el puesto? | L2: 10. ¿Cuánto tiempo hace que labora en el mismo lugar de trabajo (edificio, local o planta)? | M2: 11. Seleccione los días de la semana en trabaja usted | N2: 12. ¿Cuántas horas trabaja al día? | O2: 13. ¿Qué medio de transporte utiliza para llegar a su trabajo? | P2: 14. En caso de tener vehículo propio, ¿Cuántos tiene? | Q2: 15. En caso de contar con vehículo propio, ¿Cuánto gasta en gasolina a la semana? | R2: 16. ¿Cuánto tiempo hace de traslado a su trabajo? | S2: 17. En caso de usar transporte publico (taxi, Uber, camión) para llegar a su centro de trabajo, ¿Cuánto gasta diariamente? | T2: 18. ¿La casa o departamento en el que habita es? | U2: 19. ¿Cuántas veces a la semana consume los siguientes alimentos? [Frutas y verduras] | V2: 19. ¿Cuántas veces a la semana consume los siguientes alimentos? [Carnes Rojas y Lácteos] | W2: 19. ¿Cuántas veces a la semana consume los siguientes alimentos? [Cereales (Tortilla, Arroz, Quinoa, Papa)] | X2: 19. ¿Cuántas veces a la semana consume los siguientes alimentos? [Semillas (Cacahuate, Almendras, Pistache)] | Y2: 20. ¿Tiene la posibilidad de acceder a una alimentación sana, variada e higiénica? | Z2: 21. ¿Cuántas veces sale de vacaciones al año? | AA2: 22. En caso de tener hijos, la Educación que reciben es: | AB2: 23. ¿En qué posición realizas la mayoría de tus actividades laborales? | AC2: 24. ¿Su lugar de trabajo cuenta con ventilación? | AD2: 25. Seleccione el tipo de ventilación con la que cuenta su lugar de trabajo. | AE2: 26. La temperatura de su lugar de trabajo es: | AF2: 27. ¿Qué le produce la temperatura de su lugar de trabajo? | AG2: 28. En su lugar de trabajo se perciben olores de: | AH2: 29. ¿Cómo es la iluminación en su lugar de trabajo? | AI2: 30. De las siguientes opciones, ¿Qué le incomoda en su lugar de trabajo? | AJ2: 31. ¿En su lugar de trabajo existe ruido? | AK2: 32. El nivel de ruido en su puesto de trabajo es: | AL2: 33. El ruido en su lugar de trabajo procede de: | AM2: 34. Aproximadamente ¿Cuánto tiempo está expuesto al ruido en su área de trabajo? | AN2: 35. ¿Conoce cuál es el nivel sonoro en decibeles en su área de trabajo? | AO2: 36. ¿Existen vibraciones producidas por herramientas manuales, máquinas, vehículos, etc. en su puesto de trabajo? | AP2: 37. ¿Estás expuesto a radiaciones ionizantes o no ionizantes en tu jornada laboral? | AQ2: 38. Indique el tipo de radiación ionizante y no ionizante, al que está usted expuesto: | AR2: 39. ¿En su área de trabajo existe algún tipo de radiación ionizante? | AS2: 40. ¿Cuenta usted con equipo de protección personal para radiación ionizante? | AT2: 41. En caso de ser afirmativa la respuesta anterior, ¿Con qué tipo de equipo de protección personal cuenta? | AU2: 42. ¿Desarrolla usted trabajos en alturas mayores a 1.80 metros? | AV2: 43. En caso de ser afirmativa la respuesta anterior, ¿Con que tipo de equipo de protección personal cuenta? | AW2: 44. ¿Qué riesgos asociados al trabajo en alturas conoce? | AX2: 45. ¿Desarrolla usted trabajos con soldadura? | AY2: 46. ¿Utiliza ropa adecuada y Equipo de protección especial para la soldadura? | AZ2: 47. Conoce los riesgos y medidas preventivas en los trabajos de soldaduras contaminantes, químicos en soldadura y tipo de contaminante químico que utiliza en su área laboral. | BA2: 48. Conoce los riesgos de soldaduras, caídas en distintos niveles, pisadas sobre objetos, cortes, proyección de fragmentos y contactos eléctricos. | BB2: 49. ¿Qué tipos de riesgos de trabajo en actividades de soldadura conoce? | BC2: 50. ¿Conoce las medidas de primeros auxilios básicos para quemaduras? | BD2: 51. Su área de trabajo ¿Cuenta con botiquín de primeros auxilios? | BE2: 52. Su área de trabajo ¿Cuenta con extintores? | BF2: 53. Su área de trabajo ¿Cuenta con señaléticas de prevención de accidentes? | BG2: 54. Independientemente de la labor que realice, su área de trabajo ¿Cuenta con Equipo de Protección Personal (EPP)? | BH2: 55. En su área laboral ¿Cuenta con la capacitación suficiente para el manejo de herramientas y uso de máquinas según el tipo de área de producción y procesamiento? | BI2: 56. En su trabajo ¿Se encuentra expuesto a temperaturas elevadas? (trabajos cerca de hornos, fogones, etc.) | BJ2: 57. En su trabajo ¿Se encuentra expuesto a temperaturas abatidas? (trabajos en cuartos fríos o de refrigeración) | BK2: 58. En su puesto de trabajo, ¿Manipula sustancias o preparados nocivos o tóxicos? | BL2: 59. En caso de ser afirmativa la respuesta anterior, indique que tipo de producto químico utiliza o está expuesto: | BM2: 60. Estas sustancias o preparados, ¿Tienen alguna etiqueta o leyenda que informe de su peligrosidad? | BN2: 61. En general, la información que contiene la etiqueta (símbolos, etc.) es.. | BO2: 62. En su puesto de trabajo, ¿Respira polvos, humos, aerosoles, gases o vapores nocivos o tóxicos? (excluido el humo del tabaco) | BP2: 63. En su trabajo, ¿Maneja o tiene contacto directo con materiales que pueden ser infecciosos, tales coma desechos, fluidos corporales, materiales de laboratorio, animales? | BQ2: 64. ¿Conoce usted los posibles efectos perjudiciales para su salud de la manipulación y/o respiración de esas sustancias nocivas o tóxicas? | BR2: 65. ¿Le han informado en su empresa de las medidas a adoptar para prevenir estos posibles efectos perjudiciales? | BS2: 66. En general, el nivel de atención que debe mantener para realizar su trabajo es: | BT2: 67. En los últimos 3 meses, la cantidad de trabajo que ha tenido generalmente es: | BU2: 68. El ritmo de trabajo esta determinado por: | BV2: 69. El ritmo de trabajo es: | BW2: 70. Cuando en su puesto de trabajo se comete algún error, ¿Qué sucede? | BX2: 71. Le parece adecuado su horario de trabajo? | BY2: 72. ¿Considera que tiene que realizar tareas que no le corresponden? | BZ2: 73. ¿Hasta que punto puede tomar decisiones en su trabajo? | CA2: 74. ¿Cómo considera que son las relaciones con las personas con las que debe trabajar? [JEFES] | CB2: 74. ¿Cómo considera que son las relaciones con las personas con las que debe trabajar? [COMPAÑEROS] | CC2: 74. ¿Cómo considera que son las relaciones con las personas con las que debe trabajar? [SUBORDINADOS] | CD2: 75. ¿Existe algún obstáculo que dificulte la comunicación con sus compañeros? | CE2: 76. En caso de ser afirmativa la respuesta anterior, ¿Cuál de los siguientes aspectos dificulta esta comunicación? (Si es necesario marque mas de una respuesta) | CF2: 77. ¿Ha asistido a cursos de capacitación o formación complementaria para el desempeño de su trabajo? | CG2: 78. En caso de ser afirmativa la respuesta anterior, a ¿Cuántos cursos ha asistido? | CH2: 79. ¿Le parece suficiente la formación que le ha proporcionado la empresa en la que actualmente labora, para el desempeño de su trabajo? | CI2: 80. ¿Conoce si hay algún procedimiento establecido para la promoción del personal? | CJ2: 81. ¿Qué tipo de contrato de trabajo tiene celebrado con la empresa en la que actualmente labora? | CK2: 82. ¿Cómo cree que esta considerado su puesto de trabajo en la empresa? | CL2: 83. ¿Qué tipo de preparación necesita para desempeñar su puesto de trabajo? | CM2: 84. Además de su formación académica, ¿Para desarrollar su trabajo se requiere de aptitudes? | CN2: 85. Usted fuma o fumaba? | CO2: 86. Si la respuesta anterior fue "Si" podría especificar la cantidad de cigarros al día y los años que lleva fumando o que fumo? | CP2: 87. Si no es usted fumador, ¿Considera que el humo de tabaco de los demás perjudica su salud? | CQ2: 88. En caso de ser afirmativa la respuesta anterior, ¿Con qué frecuencia esta expuesto al humo de tabaco? | CR2: 89. Consume o consumía alcohol? | CS2: 90. Si la respuesta anterior fue "Si" pudieras especificar el tipo de alcohol (cerveza, tequila, etc.), la cantidad de consumo por semana (latas, vasos, botella) y el número de años que has consumido alcohol? | CT2: 91. Realiza actividad física? | CU2: 92. Con que frecuencia realiza actividad física a la semana (Tomando en cuenta que mínimo son 30 min al día) | CV2: 93. Seleccione si en su familia ha habido casos de: | CW2: 94. ¿Tiene usted alguno de los siguientes padecimientos heredofamiliares o crónicos degenerativos? | CX2: 95. Si la respuesta anterior fue "Otros" favor de especificar la enfermedad que padece: | CY2: 96. Si padece alguno o algunos de las padecimientos señalados en la pregunta anterior, ¿lleva algún tratamiento de control? | CZ2: 97. Favor de especificar el nombre del medicamento (os) o suplementos que consume: | DA2: 98. Alergias: Si o No y favor de especificar a que es alérgico. | DB2: 99. ¿Alguna vez ha sufrido un accidente de trabajo? | DC2: 100. En caso de ser afirmativa la respuesta anterior, mencione ¿Cuál? | DD2: 101. En su historial de trabajo, ¿ha tenido alguna incapacidad? | DE2: 102. En caso de ser afirmativa la respuesta anterior, mencione de qué tipo: | DF2: 103. ¿Consume mariguana, heroína, LSD, cocaína barbitúricos, anfetaminas o cualquier otro tipo de drogas psicoactivas? | DG2: 104. Tipo de droga: | DH2: 105. Frecuencia: | DI2: 106. Selecciona la última ocasión que consumiste | DJ2: 107. ¿Ha recibido tratamiento con relación al consumo de drogas psicoactivas? | DK2: 108. ¿Pertenece o ha pertenecido a instituciones para su rehabilitación? | DL2: 109. Las preguntas que a continuación se presentan, se refieren a síntomas que usted puede experimentar en su trabajo, por favor señale cuales son aquellos síntomas que se relacionen con usted y con que frecuencia lo presenta: Síntomas oculares [Sequedad ocular ] | DM2: 109. Las preguntas que a continuación se presentan, se refieren a síntomas que usted puede experimentar en su trabajo, por favor señale cuales son aquellos síntomas que se relacionen con usted y con que frecuencia lo presenta: Síntomas oculares [Lagrimeo] | DN2: 109. Las preguntas que a continuación se presentan, se refieren a síntomas que usted puede experimentar en su trabajo, por favor señale cuales son aquellos síntomas que se relacionen con usted y con que frecuencia lo presenta: Síntomas oculares [Enrojecimiento o comezón ocular] | DO2: 109. Las preguntas que a continuación se presentan, se refieren a síntomas que usted puede experimentar en su trabajo, por favor señale cuales son aquellos síntomas que se relacionen con usted y con que frecuencia lo presenta: Síntomas oculares [Dolor ocular ] | DP2: 109. Las preguntas que a continuación se presentan, se refieren a síntomas que usted puede experimentar en su trabajo, por favor señale cuales son aquellos síntomas que se relacionen con usted y con que frecuencia lo presenta: Síntomas oculares [Hinchazón ocular ] | DQ2: 109. Las preguntas que a continuación se presentan, se refieren a síntomas que usted puede experimentar en su trabajo, por favor señale cuales son aquellos síntomas que se relacionen con usted y con que frecuencia lo presenta: Síntomas oculares [Visión Borrosa] | DR2: 110. Las preguntas que a continuación se presentan, se refieren a síntomas que usted puede experimentar en su trabajo, por favor señale cuales son aquellos síntomas que se relacionen con usted y con que frecuencia lo presenta: Síntomas nasales [Estornudos frecuentes ] | DS2: 110. Las preguntas que a continuación se presentan, se refieren a síntomas que usted puede experimentar en su trabajo, por favor señale cuales son aquellos síntomas que se relacionen con usted y con que frecuencia lo presenta: Síntomas nasales [Sequedad nasal ] | DT2: 110. Las preguntas que a continuación se presentan, se refieren a síntomas que usted puede experimentar en su trabajo, por favor señale cuales son aquellos síntomas que se relacionen con usted y con que frecuencia lo presenta: Síntomas nasales [Congestión nasal ] | DU2: 110. Las preguntas que a continuación se presentan, se refieren a síntomas que usted puede experimentar en su trabajo, por favor señale cuales son aquellos síntomas que se relacionen con usted y con que frecuencia lo presenta: Síntomas nasales [Rinorrea (goteo o liquido nasal)] | DV2: 110. Las preguntas que a continuación se presentan, se refieren a síntomas que usted puede experimentar en su trabajo, por favor señale cuales son aquellos síntomas que se relacionen con usted y con que frecuencia lo presenta: Síntomas nasales [Pérdida del olfato ] | DW2: 110. Las preguntas que a continuación se presentan, se refieren a síntomas que usted puede experimentar en su trabajo, por favor señale cuales son aquellos síntomas que se relacionen con usted y con que frecuencia lo presenta: Síntomas nasales [Hemorragia nasal ] | DX2: 111. Síntomas de garganta [Resequedad ] | DY2: 111. Síntomas de garganta [Ronquera] | DZ2: 111. Síntomas de garganta [Irritación ] | EA2: 111. Síntomas de garganta [Dolor de garganta ] | EB2: 111. Síntomas de garganta [Sensación de cuerpo extraño ] | EC2: 111. Síntomas de garganta [Dificultad o dolor al tragar ] | ED2: 112. Síntomas bucales [Halitosis o mal aliento ] | EE2: 112. Síntomas bucales [Sequedad bucal ] | EF2: 112. Síntomas bucales [Sangrado de encías ] | EG2: 112. Síntomas bucales [Ulceras bucales ] | EH2: 112. Síntomas bucales [Lesiones o placas blanquecinas ] | EI2: 113. Síntomas cutáneos [Sequedad en la piel ] | EJ2: 113. Síntomas cutáneos [Comezón en la piel ] | EK2: 113. Síntomas cutáneos [Enrojecimiento] | EL2: 113. Síntomas cutáneos [Ampollas o vesículas ] | EM2: 113. Síntomas cutáneos [Ulceras o necrosis] | EN2: 114. Síntomas digestivos [Nauseas ] | EO2: 114. Síntomas digestivos [Pérdida del apetito] | EP2: 114. Síntomas digestivos [Estreñimiento] | EQ2: 114. Síntomas digestivos [Diarrea o vomito ] | ER2: 114. Síntomas digestivos [Dolor abdominal ] | ES2: 114. Síntomas digestivos [Heces o vomito con sangre ] | ET2: 115. Síntomas parecidos a la gripe [Cansancio o fatiga] | EU2: 115. Síntomas parecidos a la gripe [Congestion nasal ] | EV2: 115. Síntomas parecidos a la gripe [Dolor de cabeza ] | EW2: 115. Síntomas parecidos a la gripe [Tos ] | EX2: 115. Síntomas parecidos a la gripe [Fiebre ] | EY2: 115. Síntomas parecidos a la gripe [Dificultad para respirar ] | EZ2: SINTOMAS DOLOROSOS 116. A) indique si tiene molestia o dolor, su frecuencia, si le ha impedido realizar su trabajo actual, y si esa molestia o dolor se han producido coma consecuencia de las tareas que realiza en su puesto de trabajo. [Tiene dolor en esta zona ? Cuello, hombros.] | FA2: 117. ¿Con qué frecuencia? | FB2: 118. Esta molestia ¿le ha impedido realizar su trabajo? | FC2: 119. ¿Con qué frecuencia? | FD2: 120. Esta molestia ¿es consecuencia de las tareas del puesto que ocupa? | FE2: 121. Tiene dolor en alguna de estas zonas? | FF2: 122. ¿Con qué frecuencia? | FG2: 123. Esta molestia ¿le ha impedido realizar su trabajo? | FH2: 124. ¿Con que frecuencia? | FI2: 125. Esta molestia ¿es consecuencia de las tareas del puesto que ocupa? | FJ2: 126. Dolor de codos manos y/o muñecas. | FK2: 127. ¿Con que frecuencia? | FL2: 128. Esta molestia ¿le ha impedido realizar su trabajo? | FM2: 129. Con que frecuencia? | FN2: 130. Esta molestia ¿es consecuencia de las tareas del puesto que ocupa? | FO2: 131. Dolor de piernas y pies. | FP2: 132. ¿Con qué frecuencia? | FQ2: 133. Esta molestia ¿le ha impedido realizar su trabajo? | FR2: 134. ¿Con qué frecuencia? | FS2: 135. Esta molestia ¿es consecuencia de las tareas del puesto que ocupa? | FT2: 136. En su trabajo, ¿Cuánto tiempo tiene que adoptar o realizar estas posturas? SENTADO | FU2: 137. De pie | FV2: 138. Caminando | FW2: 139. Caminando mientras subo o bajo niveles diferentes (peldaños, escalera, rampa, etc.) | FX2: 140. En postura de rodillas/en cuclillas. | FY2: 141. Tumbado sobre la espalda o sobre un lado. | FZ2: 142. En su trabajo, durante cuanto tiempo tiene que adoptar o realizar estas posturas de cuello/cabeza y ¿con que frecuencia? | GA2: 143. Inclinar el cuello/cabeza | GB2: 144. Inclinar el cuello/cabeza hacia un lado o ambos | GC2: 145. En su trabajo, durante cuanto tiempo tiene que adoptar o realizar estas posturas de espalda/tronco y ¿con que frecuencia? | GD2: 146. Inclinar la espalda/tronco hacia atrás | GE2: 147. Inclinar la espalda/tronco hacia un lado o ambos | GF2: 148. Girar la espalda/tronco. | GG2: 149. En su trabajo, durante cuanto tiempo tiene que adoptar o realizar estas posturas de hombros, muñecas y tobillos/pies, y ¿con que frecuencia? Las manos por encima de la cabeza o los codos por encima de los hombros. | GH2: 150. Ejerciendo presión con uno de los pies | GI2: 151. En su trabajo, durante ¿Cuánto tiempo tiene que adoptar o realizar estas acciones con las manos? Sostener, presionar o levantar objetos o herramientas con los dedos en forma de pinza. | GJ2: 152. Agarrar o sujetar con fuerza objetos o herramientas con las manos | GK2: 153. Utilizar de manera intensiva los dedos, (ordenador, controles, botoneras, mando, calculadora, caja registradora, etc.) | GL2: 154. En su trabajo, ¿durante cuanto tiempo tiene que trabajar realizando estas acciones relacionadas con la exposición a vibraciones y/o impactos? | GM2: 155. Trabajar sobre superficies vibrantes (asiento de vehículo, plataforma o suelo vibrante, etc.) | GN2: 156. Utilizar herramientas y máquinas de impacto o vibrantes (taladro, remachadora, amoladora, martillo, grapadora neumática, etc.) | GO2: 157. Utilizar la mano (el pie o la rodilla) como martillo, golpeando de forma repetida. | GP2: Responda en relación a cada una de las acciones. 158. LEVANTAR MANUALMENTE, objetos, herramientas, materiales de mas de 3kg. ¿Durante cuanto tiempo tienes que trabajar realizando esta acción? | GQ2: 159. Los pesos que con mayor frecuencia levantas son de: | GR2: 160. Señala si habitualmente: | GS2: 161. TRANSPORTAR MANUALMENTE objetos, herramientas, materiales de mas de 3kg. ¿Durante cuanto tiempo tienes que trabajar realizando esta acción? | GT2: 162. Los pesos que con mayor frecuencia levantas son de: | GU2: 163. Señala si habitualmente: | GV2: 164. EMPUJAR Y/O ARRASTRAR MANUALMENTE utilizando algún equipo (carretilla, transpaleta, carro...) objetos, herramientas, materiales de mas de 3kg. ¿Durante cuanto tiempo tienes que trabajar realizando esta acción? | GW2: 165. Señala si habitualmente: | GX2: 166. Accidente que tenga como consecuencia la muerte, la pérdida de un miembro o una lesión grave. | GY2: 167. Actos violentos que derivaron de lesiones graves | GZ2: 168. Asaltos | HA2: 169. Secuestros | HB2: 170. Si usted ha contestado que "SI" a una o más de las preguntas anteriores, favor de contestar las siguientes: ¿Durante el último mes? | HC2: 171. ¿Ha tenido recuerdos recurrentes sobre el acontecimiento que le provocan malestares? | HD2: 172. ¿Ha tenido sueños de carácter recurrente sabre el acontecimiento, que le producen malestar? | HE2: 173. Durante el último mes ¿Se ha esforzado para evitar todo tipo de sentimientos, conversaciones o situaciones que le puedan recordar el acontecimiento? | HF2: 174. ¿Se ha esforzado para evitar todo tipo de actividades, lugares o personas que motivan recuerdos del acontecimiento? | HG2: 175. ¿Ha tenido dificultad para recordar alguna parte importante del evento? | HH2: 176. ¿Ha disminuido su interés en sus actividades cotidianas? | HI2: 177. ¿Se ha sentido usted alejado o distante de las demás? | HJ2: 178. ¿Ha notado que tiene dificultad para expresar sus sentimientos? | HK2: 179. Ha tenido la impresión de que su vida se va a acortar, ¿Qué va a morir antes que otras personas o que tiene un futuro limitado? | HL2: 180. ¿Ha estado particularmente irritable o le han dado arranques de coraje? | HM2: 181. ¿Ha tenido dificultad para concentrarse? | HN2: 182. ¿Ha estado nervioso o constantemente en alerta? | HO2: 183. ¿Se ha sobresaltado fácilmente para cualquier cosa?
A3: 1 | B3: 45841.47 | C3: Anhelo Silva Jose Hugo | D3: 27772 | E3: Servicios Juridicos | F3: Abogado | G3: Soltero | H3: Masculino | I3: Universidad | J3: Auxiliar Administrativo | K3: menos de 1 año | L3: menos de 1 año | M3: Lunes a viernes | N3: menos de 7 horas | O3: Propio | P3: 1 | Q3: De $500 a $1000 pesos | R3: 0 a 15 minutos | S3: No aplica | T3: Propia | U3: 5 o mas veces a la semana | V3: 5 o mas veces a la semana | W3: 5 o mas veces a la semana | X3: 1 a 2 veces a la semana | Y3: Si, cuento con las recursos economicos y el tiempo para acceder a mis alimentos | Z3: De 1 a 2 veces al año | AA3: No tengo hijos | AB3: Sentado | AC3: Sí | AD3: Aire acondicionado | AE3: Normal | AF3: No afecta | AG3: No se perciben olores | AH3: Adecuada a mis actividades | AI3: No le molestan estos aspectos | AJ3: Sí | AK3: Bajo – Hay algo de ruido, pero no es molesto ni afecta la concentración. | AL3: Sistema de ventilación | AM3: 1 - 3 horas | AN3: No lo conozco | AO3: Nunca | AP3: No | AU3: No | AX3: No | BC3: No | BD3: Sí | BE3: Sí | BF3: No | BG3: No | BH3: No | BI3: No | BJ3: No | BK3: No | BS3: Media | BT3: Insuficiente | BU3: No hay un ritmo prefijado | BV3: Normal | BW3: Provoca problemas menores | BX3: Sí | BY3: Nunca | BZ3: Nunca | CA3: BUENA | CB3: BUENA | CC3: BUENA | CD3: No | CE3: No hay obstáculos que dificulten la comuniación | CF3: No | CG3: 1 | CH3: Sí | CI3: No | CJ3: Indeterminado | CK3: Poco importante | CL3: Formación superior | CM3: Muy pocas | CN3: No | CO3: No fumo | CP3: No | CQ3: No aplica | CR3: Si | CS3: 5 veces por semana | CT3: Si | CU3: Mas de 5 días a la semana | CV3: Cáncer, Diabetes, Enfermedades del corazón, Presión arterial alta | CW3: Ninguna | CX3: No | CY3: No aplica | CZ3: No | DA3: No | DB3: No | DC3: No | DD3: No | DE3: No | DF3: Sí | DG3: Cocaina | DH3: Frecuentemente (todos los días) | DI3: En la última semana | DJ3: No | DK3: No | DL3: Muchas veces | DM3: Muchas veces | DN3: Muchas veces | DO3: Muchas veces | DP3: Muchas veces | DQ3: Muchas veces | DR3: Muchas veces | DS3: Muchas veces | DT3: Muchas veces | DU3: Muchas veces | DV3: Muchas veces | DW3: Muchas veces | DX3: Nunca | DY3: Nunca | DZ3: Nunca | EA3: Nunca | EB3: Nunca | EC3: Nunca | ED3: Nunca | EE3: Nunca | EF3: Nunca | EG3: Nunca | EH3: Nunca | EI3: Nunca | EJ3: Nunca | EK3: Nunca | EL3: Nunca | EM3: Nunca | EN3: A veces | EO3: A veces | EP3: A veces | EQ3: Nunca | ER3: A veces | ES3: Nunca | ET3: A veces | EU3: A veces | EV3: A veces | EW3: A veces | EX3: Nunca | EY3: Nunca | EZ3: Nunca | FA3: Nunca | FB3: No | FC3: Nunca | FD3: No | FE3: Nunca | FF3: Nunca | FG3: Nunca | FH3: Nunca | FI3: No | FJ3: A veces | FK3: Rara vez (una vez al mes o menos) | FL3: No | FM3: Rara vez (una vez al mes o menos) | FN3: No | FO3: Sí | FP3: Regularmente (algunas veces a la semana) | FQ3: A veces | FR3: Rara vez (una vez al mes o menos) | FS3: No | FT3: Mas de 4 horas | FU3: Menos de 30 minutos | FV3: Entre 2 y 4 horas | FW3: Entre 30 min y 2 horas | FX3: Nunca | FY3: Nunca | FZ3: Nunca | GA3: Nunca | GB3: Nunca | GC3: Nunca | GD3: Nunca | GE3: Nunca | GF3: Nunca | GG3: Nunca | GH3: Nunca | GI3: Menos de 30 minutos | GJ3: Menos de 30 minutos | GK3: Entre 2 y 4 horas | GL3: Menos de 30 minutos | GM3: Menos de 30 minutos | GN3: Menos de 30 minutos | GO3: Menos de 30 minutos | GP3: Menos de 30 minutos | GQ3: Mas de 25 kilos | GR3: Levantas la carga tu solo/a (sin ayuda de otra persona) | GS3: Menos de 30 minutos | GT3: Mas de 25 kilos | GU3: Transportas la carga tu solo/a (sin ayuda de otra persona) | GV3: Menos de 30 minutos | GW3: Tienes que hacer mucha fuerza para iniciar el empuje y/o arrastre | GX3: No | GY3: No | GZ3: No | HA3: No | HB3: No | HC3: No | HD3: No | HE3: No | HF3: No | HG3: Sí | HH3: Sí | HI3: Sí | HJ3: Sí | HK3: Sí | HL3: Sí | HM3: Sí | HN3: No | HO3: No
A4: 2 | B4: 45844.407 | C4: Gómez Rodríguez Alejandra | D4: 31842 | E4: Departamento de contabilidad y auditoría | F4: Contador general | G4: Casado | H4: Femenino | I4: Universidad | J4: Auxiliar Administrativo | K4: 3 a 6 años | L4: 2 a 3 años | M4: Lunes a viernes | N4: 8 horas | O4: Propio | P4: 1 | Q4: De $500 a $1000 pesos | R4: 31 a 45 minutos | S4: No aplica | T4: Rentada | U4: 3 a 4 veces a la semana | V4: 1 a 2 veces a la semana | W4: 5 o mas veces a la semana | X4: 1 a 2 veces a la semana | Y4: Si, cuento con las recursos economicos y el tiempo para acceder a mis alimentos | Z4: De 1 a 2 veces al año | AA4: Pública | AB4: Sentado | AC4: Sí | AD4: Aire acondicionado | AE4: Normal | AF4: No afecta | AG4: Comida | AH4: Intensa | AI4: La distribución y orden del espacio, Perturbaciones o distracciones | AJ4: Sí | AK4: Alto – El ruido es notable y puede resultar molesto, afectando la concentración y productividad. | AL4: Conversaciones | AM4: 3 - 5 horas | AN4: No lo conozco | AO4: Nunca | AP4: No | AU4: No | AX4: No | BC4: No | BD4: Sí | BE4: Sí | BF4: Sí | BG4: No | BH4: Sí | BI4: No | BJ4: No | BK4: No | BS4: Media | BT4: Suficiente | BU4: Causas externas: publico/clientes | BV4: Normal | BW4: Produce consecuencias graves | BX4: Sí | BY4: A menudo | BZ4: Algunas Veces | CA4: BUENA | CB4: BUENA | CC4: BUENA | CD4: No | CE4: No hay obstáculos que dificulten la comuniación | CF4: Sí | CG4: Más de 4 | CH4: Sí | CI4: No | CJ4: Determinado | CK4: Importante | CL4: Formación superior | CM4: Bastantes | CN4: No | CP4: Sí | CQ4: Ocasionalmente (algunas veces al mes) | CR4: Si | CS4: 1-2 latas de cerveza por semana por 10 años, de forma intermitente. | CT4: Si | CU4: 1 o 2 días a la semana | CV4: Diabetes, Presión arterial alta | CW4: Ninguna | CY4: No aplica | CZ4: Complejo B, vitamina C | DA4: Penicilina | DB4: No | DC4: No he sufrido un accidente | DD4: Si | DE4: Secundaria a un esguince de tobillo | DF4: No | DG4: No uso drogas | DH4: Nunca | DI4: No aplica | DJ4: No | DK4: No | DL4: A veces | DM4: Nunca | DN4: A veces | DO4: A veces | DP4: Nunca | DQ4: Nunca | DR4: Nunca | DS4: A veces | DT4: A veces | DU4: Nunca | DV4: Nunca | DW4: Nunca | DX4: A veces | DY4: Nunca | DZ4: Nunca | EA4: Nunca | EB4: Nunca | EC4: Nunca | ED4: Nunca | EE4: Nunca | EF4: Nunca | EG4: Nunca | EH4: Nunca | EI4: A veces | EJ4: A veces | EK4: Nunca | EL4: Nunca | EM4: Nunca | EN4: Nunca | EO4: Nunca | EP4: A veces | EQ4: Nunca | ER4: A veces | ES4: Nunca | ET4: A veces | EU4: Nunca | EV4: A veces | EW4: Nunca | EX4: Nunca | EY4: Nunca | EZ4: A veces | FA4: Regularmente (algunas veces a la semana) | FB4: No | FC4: Nunca | FD4: Si | FE4: A veces | FF4: Regularmente (algunas veces a la semana) | FG4: No | FH4: Nunca | FI4: Si | FJ4: No | FK4: Nunca | FL4: No | FM4: Nunca | FN4: No | FO4: Sí | FP4: Frecuentemente (todos los días) | FQ4: No | FR4: Nunca | FS4: Si | FT4: Mas de 4 horas | FU4: Entre 30 min y 2 horas | FV4: Menos de 30 minutos | FW4: Menos de 30 minutos | FX4: Nunca | FY4: Nunca | FZ4: Entre 2 y 4 horas | GA4: Menos de 30 minutos | GB4: Menos de 30 minutos | GC4: Menos de 30 minutos | GD4: Nunca | GE4: Nunca | GF4: Nunca | GG4: Nunca | GH4: Nunca | GI4: Nunca | GJ4: Nunca | GK4: Mas de 4 horas | GL4: Nunca | GM4: Nunca | GN4: Nunca | GO4: Nunca | GP4: Nunca | GQ4: No levanto peso | GR4: No levanto peso | GS4: Nunca | GT4: No levanto peso | GU4: No levanto peso | GV4: Nunca | GW4: No empujo | GX4: No | GY4: No | GZ4: Si | HA4: No | HB4: No | HC4: No | HD4: No | HE4: No | HF4: No | HG4: No | HH4: No | HI4: No | HJ4: Sí | HK4: No | HL4: Sí | HM4: No | HN4: No | HO4: No
A5: 3 | B5: 45845.57 | C5: Jorge Ferrer López | D5: 29479 | E5: Departamento Jurídico | F5: Abogado | G5: Casado | H5: Masculino | I5: Posgrado | J5: Mandos Medios | K5: 18 a 21 años | L5: mas de 3 años | M5: Lunes a viernes | N5: 8 horas | O5: Propio | P5: 2 | Q5: Mas de $1500 pesos | R5: 31 a 45 minutos | S5: No aplica | T5: Propia | U5: 3 a 4 veces a la semana | V5: 5 o mas veces a la semana | W5: 3 a 4 veces a la semana | X5: 3 a 4 veces a la semana | Y5: Si, cuento con las recursos economicos y el tiempo para acceder a mis alimentos | Z5: De 1 a 2 veces al año | AA5: Privada | AB5: Sentado | AC5: Sí | AD5: Aire acondicionado | AE5: Frío | AF5: Alergia | AG5: Corporales (sudor, mal aliento, olor a pies, orina, heces, flatulencias) | AH5: Intensa | AI5: La distribución y orden del espacio, Sentimiento de encierro, Falta de socialización laboral, Aislamiento | AJ5: Sí | AK5: Bajo – Hay algo de ruido, pero no es molesto ni afecta la concentración. | AL5: Conversaciones | AM5: 3 - 5 horas | AN5: No lo conozco | AO5: Algunas veces | AP5: No | AU5: No | AX5: No | BC5: No | BD5: No | BE5: Sí | BF5: No | BG5: No | BH5: No | BI5: No | BJ5: No | BK5: No | BS5: Media | BT5: Excesiva | BU5: No hay un ritmo prefijado | BV5: Apresurado | BW5: Entorpece el trabajo | BX5: Sí | BY5: A veces | BZ5: Siempre | CA5: BUENA | CB5: BUENA | CC5: BUENA | CD5: No | CE5: No hay obstáculos que dificulten la comuniación | CF5: Sí | CG5: 2 | CH5: Sí | CI5: No | CJ5: Indeterminado | CK5: Importante | CL5: Formación superior | CM5: Bastantes | CN5: No | CP5: Sí | CQ5: Frecuentemente (todos los días) | CR5: Si | CS5: Tequila, un día de la semana | CT5: No | CU5: No realizo | CV5: Cáncer, Diabetes, Enfermedades del corazón, Enfermedades de los riñones | CW5: Ninguna | CY5: No aplica | CZ5: No consumo | DA5: No | DB5: No | DC5: No sufrí accidentes de trabajo | DD5: Si | DE5: Estrés, vista borrosa, ansiedad, migraña | DF5: No | DG5: No aplica | DH5: Nunca | DI5: No aplica | DJ5: No | DK5: No | DL5: Muchas veces | DM5: A veces | DN5: Muchas veces | DO5: Nunca | DP5: Nunca | DQ5: Muchas veces | DR5: Nunca | DS5: Nunca | DT5: Nunca | DU5: Nunca | DV5: Nunca | DW5: Nunca | DX5: A veces | DY5: A veces | DZ5: A veces | EA5: Muchas veces | EB5: Nunca | EC5: A veces | ED5: Nunca | EE5: Nunca | EF5: A veces | EG5: Nunca | EH5: Nunca | EI5: A veces | EJ5: Nunca | EK5: Nunca | EL5: Nunca | EM5: Nunca | EN5: Nunca | EO5: Nunca | EP5: Muchas veces | EQ5: A veces | ER5: Muchas veces | ES5: Nunca | ET5: Nunca | EU5: Nunca | EV5: Muchas veces | EW5: A veces | EX5: Nunca | EY5: Nunca | EZ5: A veces | FA5: Rara vez (una vez al mes o menos) | FB5: No | FC5: Nunca | FD5: Si | FE5: Sí | FF5: Rara vez (una vez al mes o menos) | FG5: No | FH5: Nunca | FI5: Si | FJ5: No | FK5: Nunca | FL5: No | FM5: Nunca | FN5: No | FO5: No | FP5: Nunca | FQ5: No | FR5: Nunca | FS5: No | FT5: Mas de 4 horas | FU5: Menos de 30 minutos | FV5: Menos de 30 minutos | FW5: Nunca | FX5: Nunca | FY5: Nunca | FZ5: Entre 2 y 4 horas | GA5: Nunca | GB5: Nunca | GC5: Nunca | GD5: Nunca | GE5: Nunca | GF5: Nunca | GG5: Nunca | GH5: Nunca | GI5: Nunca | GJ5: Nunca | GK5: Mas de 4 horas | GL5: Nunca | GM5: Nunca | GN5: Nunca | GO5: Nunca | GP5: Nunca | GQ5: No levanto peso | GR5: No levanto peso | GS5: Nunca | GT5: No levanto peso | GU5: No levanto peso | GV5: Nunca | GW5: No empujo | GX5: Sí | GY5: No | GZ5: No | HA5: No | HB5: No | HC5: No | HD5: Sí | HE5: Sí | HF5: No | HG5: No | HH5: Sí | HI5: No | HJ5: Sí | HK5: No | HL5: Sí | HM5: Sí | HN5: No | HO5: No
A6: 4 | B6: 45846.483 | C6: PERLA VIRIDIANA GONZALEZ ESPARZA | D6: 33994 | E6: Administración | F6: Auxiliar Administrativo | G6: Soltero | H6: Femenino | I6: Universidad | J6: Auxiliar Administrativo | K6: 6 a 9 años | L6: mas de 3 años | M6: Lunes a viernes | N6: 8 horas | O6: Público | P6: No tengo | Q6: No aplica | R6: mas de 1 hora | S6: De $50 a $100 pesos | T6: Propia | U6: 1 a 2 veces a la semana | V6: 3 a 4 veces a la semana | W6: 5 o mas veces a la semana | X6: 3 a 4 veces a la semana | Y6: No, el ritmo de trabajo no me permite comprar y preparar mis alimentos | Z6: De 1 a 2 veces al año | AA6: No tengo hijos | AB6: Sentado | AC6: Sí | AD6: Aire acondicionado | AE6: Normal | AF6: No afecta | AG6: No se perciben olores | AH6: Adecuada a mis actividades | AI6: No le molestan estos aspectos | AJ6: No | AO6: Nunca | AP6: No | AU6: No | AX6: No | BC6: No | BD6: No | BE6: Sí | BF6: No | BG6: No | BH6: No | BI6: No | BJ6: No | BK6: No | BS6: Alta | BT6: Suficiente | BU6: Objetivos que hay que alcanzar | BV6: Apresurado | BW6: Provoca problemas menores | BX6: Sí | BY6: A menudo | BZ6: Algunas Veces | CA6: BUENA | CB6: BUENA | CC6: BUENA | CD6: No | CE6: No hay obstáculos que dificulten la comuniación | CF6: Sí | CG6: 1 | CH6: Sí | CI6: Sí | CJ6: Indeterminado | CK6: De los mas importantes | CL6: Formación superior | CM6: Bastantes | CN6: No | CP6: Sí | CQ6: Rara vez (una vez al mes o menos) | CR6: Si | CS6: Tequila, no he consumido durante mucho tiempo y aproximadamente 9 años | CT6: Si | CU6: 1 o 2 días a la semana | CV6: Diabetes, Presión arterial alta | CW6: Ninguna | CY6: No aplica | CZ6: No consumo | DA6: NO | DB6: No | DC6: NO | DD6: No | DE6: NINGUNA | DF6: No | DG6: NINGUNA | DH6: Nunca | DI6: No aplica | DJ6: No | DK6: No | DL6: A veces | DM6: Nunca | DN6: Nunca | DO6: Nunca | DP6: Nunca | DQ6: Nunca | DR6: A veces | DS6: Nunca | DT6: A veces | DU6: A veces | DV6: Nunca | DW6: Nunca | DX6: Muchas veces | DY6: A veces | DZ6: A veces | EA6: Muchas veces | EB6: A veces | EC6: A veces | ED6: Nunca | EE6: Nunca | EF6: Nunca | EG6: Nunca | EH6: Nunca | EI6: Nunca | EJ6: Nunca | EK6: Nunca | EL6: Nunca | EM6: Nunca | EN6: A veces | EO6: Nunca | EP6: Nunca | EQ6: A veces | ER6: A veces | ES6: Nunca | ET6: A veces | EU6: A veces | EV6: A veces | EW6: A veces | EX6: A veces | EY6: Nunca | EZ6: Si | FA6: Ocasionalmente (algunas veces al mes) | FB6: No | FC6: Nunca | FD6: Si | FE6: A veces | FF6: Rara vez (una vez al mes o menos) | FG6: No | FH6: Nunca | FI6: Si | FJ6: Sí | FK6: Regularmente (algunas veces a la semana) | FL6: A veces | FM6: Rara vez (una vez al mes o menos) | FN6: Si | FO6: A veces | FP6: Regularmente (algunas veces a la semana) | FQ6: No | FR6: Nunca | FS6: No | FT6: Mas de 4 horas | FU6: Menos de 30 minutos | FV6: Menos de 30 minutos | FW6: Nunca | FX6: Nunca | FY6: Nunca | FZ6: Entre 30 min y 2 horas | GA6: Nunca | GB6: Nunca | GC6: Nunca | GD6: Nunca | GE6: Nunca | GF6: Nunca | GG6: Nunca | GH6: Nunca | GI6: Nunca | GJ6: Nunca | GK6: Mas de 4 horas | GL6: Nunca | GM6: Nunca | GN6: Nunca | GO6: Nunca | GP6: Nunca | GQ6: No levanto peso | GR6: No levanto peso | GS6: Nunca | GT6: No levanto peso | GU6: No levanto peso | GV6: Nunca | GW6: No empujo | GX6: No | GY6: No | GZ6: No | HA6: No | HB6: No | HC6: No | HD6: No | HE6: No | HF6: No | HG6: No | HH6: No | HI6: No | HJ6: No | HK6: No | HL6: No | HM6: No | HN6: No | HO6: No
A7: 5 | B7: 45869.896 | C7: Prueba 1 | D7: 33637 | E7: Arquitectos | F7: Arquitecto | G7: Soltero | H7: Femenino | I7: Universidad | J7: Auxiliar Administrativo | K7: 1 a 3 años | L7: 1 a 2 años | M7: Lunes a viernes | N7: 10 horas | O7: Plataforma (Uber, DIDI u otros) | P7: No tengo | Q7: No aplica | R7: 45 a 60 minutos | S7: Más de $100 pesos | T7: Prestada | U7: No consumo | V7: No consumo | W7: No consumo | X7: No consumo | Y7: No, el ritmo de trabajo no me permite comprar y preparar mis alimentos | Z7: Ninguna | AA7: No estudian | AB7: Ambos | AC7: Sí | AD7: Ventana o natural | AE7: Normal | AF7: Resequedad | AG7: Corporales (sudor, mal aliento, olor a pies, orina, heces, flatulencias) | AH7: Adecuada a mis actividades | AI7: La distribución y orden del espacio, Perturbaciones o distracciones, La falta de limpieza, Sentimiento de encierro, La decoración, La alfombra en el suelo y/o pared, Falta de socialización laboral, Aislamiento | AJ7: Sí | AK7: Muy alto – El ruido es muy fuerte y constante, impidiendo la concentración y generando incomodidad. | AL7: Maquinaria y/o equipos de producción | AM7: 5 horas o más | AN7: No lo conozco | AO7: Siempre | AP7: Sí | AQ7: Luz ultravioleta (soldadura eléctrica al arco, lámparas, germicidas…), excluida la luz solar, Luz infrarroja, Microondas (hornos de secado, antenas de telefonía móvil…), Radiofrecuencias (soldaduras por radiofrecuencias, calentamiento de bajíos…), Rayos lasser, Rayos X, rayos gamma, radioisótopos (radiodiagnóstico, radioterapia, diagnóstico de soldaduras) | AR7: Si | AS7: Sí | AT7: Guantes plomizos (para rayos x) | AU7: Sí | AV7: Líneas de vida y de anclaje | AW7: Caídas de distinto nivel en metros | AX7: Sí | AY7: Si | AZ7: Sí | BA7: Sí | BB7: Contacto con superficies calientes o flamas | BC7: Sí | BD7: Sí | BE7: Sí | BF7: Sí | BG7: Sí | BH7: Sí | BI7: Sí | BJ7: Sí | BK7: Sí | BL7: Hidrocarburos. (gasolina, Diesel, turbosina, etc.) | BM7: Si, todos | BN7: Complicada | BO7: Sí | BP7: Si, de forma deliberada o intencionada: laboratorios de diagnóstico microbiológico, trabajo con animales, obtención de vacunas, insulina u otros medicamentos, procesos de fermentación. | BQ7: Sí | BR7: Sí | BS7: Alta | BT7: Excesiva | BU7: El ritmo de una maquina o línea | BV7: Apresurado | BW7: Produce consecuencias graves | BX7: Sí | BY7: A menudo | BZ7: Siempre | CA7: MALA | CB7: MALA | CC7: MALA | CD7: Sí | CE7: La normatividad de la empresa, El inmediato superior, El ritmo de trabajo, No poder desviar la atención del trabajo, No hay obstáculos que dificulten la comuniación | CF7: Sí | CG7: 1 | CH7: No | CI7: No | CJ7: Determinado | CK7: Poco importante | CL7: Formación técnica | CM7: Bastantes | CN7: Si | CO7: 2 x día | CP7: Sí | CQ7: Regularmente (algunas veces a la semana) | CR7: Si | CS7: una copa diaria | CT7: Si | CU7: Mas de 5 días a la semana | CV7: Cáncer, Diabetes, Enfermedades del corazón, Presión arterial alta, Enfermedades de los riñones, Enfermedades cerebrovasculares, Enfermedades mentales, Intento de Suicidio, Enfermedades reumatológicas | CW7: Hipertensión Arterial Esencial, Obesidad Mórbida, Diabetes Mellitus tipo II, Otros | CX7: varias | CY7: No | CZ7: aspirina | DA7: si, al polvo | DB7: Si | DC7: me cai | DD7: Si | DE7: me rompi la nariz | DF7: Sí | DG7: heroina | DH7: Frecuentemente (todos los días) | DI7: En la última semana | DJ7: Sí | DK7: Sí | DL7: Muchas veces | DM7: Muchas veces | DN7: Muchas veces | DO7: Muchas veces | DP7: Muchas veces | DQ7: Muchas veces | DR7: Muchas veces | DS7: Muchas veces | DT7: Muchas veces | DU7: Muchas veces | DV7: Muchas veces | DW7: Muchas veces | DX7: Muchas veces | DY7: Muchas veces | DZ7: Muchas veces | EA7: Muchas veces | EB7: Muchas veces | EC7: Muchas veces | ED7: Muchas veces | EE7: Muchas veces | EF7: Muchas veces | EG7: Muchas veces | EH7: Muchas veces | EI7: Muchas veces | EJ7: Muchas veces | EK7: Muchas veces | EL7: Muchas veces | EM7: Muchas veces | EN7: Muchas veces | EO7: Muchas veces | EP7: Muchas veces | EQ7: Muchas veces | ER7: Muchas veces | ES7: Muchas veces | ET7: Muchas veces | EU7: Muchas veces | EV7: Muchas veces | EW7: Muchas veces | EX7: Muchas veces | EY7: Muchas veces | EZ7: Si | FA7: Frecuentemente (todos los días) | FB7: Sí | FC7: Frecuentemente (todos los días) | FD7: Si | FE7: Sí | FF7: Frecuentemente (todos los días) | FG7: Sí | FH7: Frecuentemente (todos los días) | FI7: Si | FJ7: Sí | FK7: Frecuentemente (todos los días) | FL7: Sí | FM7: Frecuentemente (todos los días) | FN7: Si | FO7: Sí | FP7: Frecuentemente (todos los días) | FQ7: Sí | FR7: Frecuentemente (todos los días) | FS7: Si | FT7: Mas de 4 horas | FU7: Mas de 4 horas | FV7: Mas de 4 horas | FW7: Mas de 4 horas | FX7: Mas de 4 horas | FY7: Mas de 4 horas | FZ7: Mas de 4 horas | GA7: Mas de 4 horas | GB7: Mas de 4 horas | GC7: Mas de 4 horas | GD7: Mas de 4 horas | GE7: Mas de 4 horas | GF7: Mas de 4 horas | GG7: Mas de 4 horas | GH7: Mas de 4 horas | GI7: Mas de 4 horas | GJ7: Mas de 4 horas | GK7: Mas de 4 horas | GL7: Mas de 4 horas | GM7: Mas de 4 horas | GN7: Mas de 4 horas | GO7: Mas de 4 horas | GP7: Mas de 4 horas | GQ7: Mas de 25 kilos | GR7: Levantas la carga con dificultad por no tener buen agarre (sin asa) | GS7: Mas de 4 horas | GT7: Mas de 25 kilos | GU7: Tienes que transportar la carga cada pocos segundos | GV7: Mas de 4 horas | GW7: Tienes que empujar y/o arrastrar la carga cada pocos segundos | GX7: Sí | GY7: Sí | GZ7: Sí | HA7: Sí | HB7: Sí | HC7: Sí | HD7: Sí | HE7: Sí | HF7: Sí | HG7: Sí | HH7: Sí | HI7: Sí | HJ7: Sí | HK7: Sí | HL7: Sí | HM7: Sí | HN7: Sí | HO7: Sí
A8: 6 | B8: 2025/07/07 1:41:03 PM CST | C8: Jorge Ferrer LÃ³pez | D8: 29479 | E8: Departamento JurÃ­dico | F8: Abogado | G8: Casado | H8: Masculino | I8: Posgrado | J8: Mandos Medios | K8: 18 a 21 | L8: mas de 3 aÃ±os | M8: Lunes a viernes | N8: 8 horas | O8: Propio | P8: 2 | Q8: Mas de $1500 pesos | R8: 31 a 45 minutos | S8: No aplica | T8: Propia | U8: 3 a 4 veces a la semana | V8: 5 o mas veces a la semana | W8: 3 a 4 veces a la semana | X8: 3 a 4 veces a la semana | Y8: Si, cuento con las recursos economicos y el tiempo para acceder a mis alimentos | Z8: De 1 a 2 veces al aÃ±o | AA8: Privada | AB8: Sentado | AC8: SÃ­ | AD8: Aire acondicionado | AE8: FrÃ­o | AF8: Alergia | AG8: Corporales (sudor, mal aliento, olor a pies, orina, heces, flatulencias) | AH8: Intensa | AI8: La distribuciÃ³n y orden del espacio;Sentimiento de encierro;Falta de socializaciÃ³n laboral;Aislamiento | AJ8: SÃ­ | AK8: Bajo â€“ Hay algo de ruido, pero no es molesto ni afecta la concentraciÃ³n. | AL8: Conversaciones | AM8: 3 - 5 horas | AN8: No lo conozco | AO8: Algunas veces | AP8: No | AU8: No | AX8: No | BC8: No | BD8: No | BE8: SÃ­ | BF8: No | BG8: No | BH8: No | BI8: No | BJ8: No | BK8: No | BS8: Media | BT8: Excesiva | BU8: No hay un ritmo prefijado | BV8: Apresurado | BW8: Entorpece el trabajo | BX8: SÃ­ | BY8: A veces | BZ8: Siempre | CA8: BUENA | CB8: BUENA | CC8: BUENA | CD8: No | CE8: No hay obstÃ¡culos que dificulten la comuniaciÃ³n | CF8: SÃ­ | CG8: 2 | CH8: SÃ­ | CI8: No | CJ8: Indeterminado | CK8: Importante | CL8: FormaciÃ³n superior | CM8: Bastantes | CN8: No | CP8: SÃ­ | CQ8: Frecuentemente (todos los dÃ­as) | CR8: Si | CS8: Tequila, un dÃ­a de la semana | CT8: No | CU8: No realizo | CV8: CÃ¡ncer;Diabetes;Enfermedades del corazÃ³n;Enfermedades de los riÃ±ones | CW8: Ninguna | CY8: No aplica | CZ8: No consumo | DA8: No | DB8: No | DC8: No sufrÃ­ accidentes de trabajo | DD8: Si | DE8: EstrÃ©s, vista borrosa, ansiedad, migraÃ±a | DF8: No | DG8: No aplica | DH8: Nunca | DI8: No aplica | DJ8: No | DK8: No | DL8: Muchas veces | DM8: A veces | DN8: Muchas veces | DO8: Nunca | DP8: Nunca | DQ8: Muchas veces | DR8: Nunca | DS8: Nunca | DT8: Nunca | DU8: Nunca | DV8: Nunca | DW8: Nunca | DX8: A veces | DY8: A veces | DZ8: A veces | EA8: Muchas veces | EB8: Nunca | EC8: A veces | ED8: Nunca | EE8: Nunca | EF8: A veces | EG8: Nunca | EH8: Nunca | EI8: A veces | EJ8: Nunca | EK8: Nunca | EL8: Nunca | EM8: Nunca | EN8: Nunca | EO8: Nunca | EP8: Muchas veces | EQ8: A veces | ER8: Muchas veces | ES8: Nunca | ET8: Nunca | EU8: Nunca | EV8: Muchas veces | EW8: A veces | EX8: Nunca | EY8: Nunca | EZ8: A veces | FA8: Rara vez (una vez al mes o menos) | FB8: No | FC8: Nunca | FD8: Si | FE8: SÃ­ | FF8: Rara vez (una vez al mes o menos) | FG8: No | FH8: Nunca | FI8: Si | FJ8: No | FK8: Nunca | FL8: No | FM8: Nunca | FN8: No | FO8: No | FP8: Nunca | FQ8: No | FR8: Nunca | FS8: No | FT8: Mas de 4 horas | FU8: Menos de 30 minutos | FV8: Menos de 30 minutos | FW8: Nunca | FX8: Nunca | FY8: Nunca | FZ8: Entre 2 y 4 horas | GA8: Nunca | GB8: Nunca | GC8: Nunca | GD8: Nunca | GE8: Nunca | GF8: Nunca | GG8: Nunca | GH8: Nunca | GI8: Nunca | GJ8: Nunca | GK8: Mas de 4 horas | GL8: Nunca | GM8: Nunca | GN8: Nunca | GO8: Nunca | GP8: Nunca | GQ8: No levanto peso | GR8: No levanto peso | GS8: Nunca | GT8: No levanto peso | GU8: No levanto peso | GV8: Nunca | GW8: No empujo | GX8: SÃ­ | GY8: No | GZ8: No | HA8: No | HB8: No | HC8: No | HD8: SÃ­ | HE8: SÃ­ | HF8: No | HG8: No | HH8: SÃ­ | HI8: No | HJ8: SÃ­ | HK8: No | HL8: SÃ­ | HM8: SÃ­ | HN8: No | HO8: No
A9: 7 | B9: 2025/09/09 1:08:13 PM CST | C9: jfl | D9: 29564 | E9: j | F9: f | G9: Casado | H9: Masculino | I9: Secundaria | J9: Supervisor Administrativo | K9: 9 a 12 aÃ±os | L9: 1 a 2 aÃ±os | M9: Lunes a sabado | N9: 9 horas | O9: Propio | P9: 3 | Q9: Mas de $1500 pesos | R9: 31 a 45 minutos | S9: De $50 a $100 pesos | T9: Rentada | U9: 3 a 4 veces a la semana | V9: 3 a 4 veces a la semana | W9: 3 a 4 veces a la semana | X9: 3 a 4 veces a la semana | Y9: No, el ritmo de trabajo no me permite comprar y preparar mis alimentos | Z9: Mas de 3 veces al aÃ±o | AA9: Privada | AB9: Sentado | AC9: No | AD9: Aire acondicionado | AE9: Normal | AF9: No afecta | AG9: No se perciben olores | AH9: Adecuada a mis actividades | AI9: No le molestan estos aspectos | AJ9: No | AO9: Algunas veces | AP9: No | AU9: No | AX9: No | BC9: SÃ­ | BD9: SÃ­ | BE9: SÃ­ | BF9: No | BG9: No | BH9: No | BI9: No | BJ9: No | BK9: No | BS9: Alta | BT9: Excesiva | BU9: No hay un ritmo prefijado | BV9: Apresurado | BW9: Produce consecuencias graves | BX9: No | BY9: A menudo | BZ9: Siempre | CA9: BUENA | CB9: BUENA | CC9: BUENA | CD9: No | CE9: El ritmo de trabajo | CF9: SÃ­ | CG9: 2 | CH9: No | CI9: No | CJ9: Indeterminado | CK9: Importante | CL9: FormaciÃ³n media | CM9: Muy pocas | CN9: No | CO9: no aplica | CP9: SÃ­ | CQ9: Rara vez (una vez al mes o menos) | CR9: Si | CT9: Si | CU9: 3 o 5 dÃ­as a la semana | CV9: Diabetes;Enfermedades del corazÃ³n | CW9: Diabetes Mellitus tipo II | CX9: no aplica | CY9: No | CZ9: no aplica | DA9: no aplica | DB9: Si | DC9: no aplica | DD9: Si | DE9: no aplica | DF9: SÃ­ | DG9: no aplica | DH9: Rara vez (una vez al mes o menos) | DI9: Hace entre 6 meses y un aÃ±o | DJ9: No | DK9: No | DL9: A veces | DM9: A veces | DN9: A veces | DO9: A veces | DP9: A veces | DQ9: A veces | DR9: A veces | DS9: A veces | DT9: A veces | DU9: A veces | DV9: A veces | DW9: A veces | DX9: A veces | DY9: A veces | DZ9: A veces | EA9: A veces | EB9: A veces | EC9: A veces | ED9: A veces | EE9: A veces | EF9: A veces | EG9: A veces | EH9: A veces | EI9: A veces | EJ9: A veces | EK9: A veces | EL9: A veces | EM9: A veces | EN9: A veces | EO9: A veces | EP9: A veces | EQ9: A veces | ER9: A veces | ES9: A veces | ET9: A veces | EU9: A veces | EV9: A veces | EW9: A veces | EX9: A veces | EY9: A veces | EZ9: A veces | FA9: Rara vez (una vez al mes o menos) | FB9: No | FC9: Ocasionalmente (algunas veces al mes) | FD9: No | FE9: A veces | FF9: Rara vez (una vez al mes o menos) | FG9: No | FH9: Ocasionalmente (algunas veces al mes) | FI9: Si | FJ9: A veces | FK9: Regularmente (algunas veces a la semana) | FL9: A veces | FM9: Regularmente (algunas veces a la semana) | FN9: Si | FO9: No | FP9: Nunca | FQ9: No | FR9: Rara vez (una vez al mes o menos) | FS9: Si | FT9: Entre 30min y 2 horas | FU9: Entre 30 min y 2 horas | FV9: Entre 30 min y 2 horas | FW9: Entre 2 y 4 horas | FX9: Entre 30 min y 2 horas | FY9: Entre 30 min y 2 horas | FZ9: Entre 30 min y 2 horas | GA9: Entre 2 y 4 horas | GB9: Entre 2 y 4 horas | GC9: Entre 2 y 4 horas | GD9: Entre 2 y 4 horas | GE9: Entre 2 y 4 horas | GF9: Entre 30 min y 2 horas | GG9: Entre 2 y 4 horas | GH9: Entre 2 y 4 horas | GI9: Entre 30 min y 2 horas | GJ9: Entre 2 y 4 horas | GK9: Entre 2 y 4 horas | GL9: Entre 2 y 4 horas | GM9: Mas de 4 horas | GN9: Entre 30 min y 2 horas | GO9: Entre 2 y 4 horas | GP9: Entre 30 min y 2 horas | GQ9: Entre 5 y 15 kilos | GR9: Mantienes los brazos extendidos sin poder apoyar la carga en tu cuerpo | GS9: Entre 30 min y 2 horas | GT9: Entre 5 y 15 kilos | GU9: Transportas la carga con dificultad porno tener buen agarre (sin asa) | GV9: Entre 2 y 4 horas | GW9: Tienes que hacer mucha fuerza para desplazar la carga | GX9: No | GY9: No | GZ9: SÃ­ | HA9: SÃ­ | HB9: No | HC9: SÃ­ | HD9: SÃ­ | HE9: SÃ­ | HF9: No | HG9: No | HH9: SÃ­ | HI9: SÃ­ | HJ9: SÃ­ | HK9: No | HL9: SÃ­ | HM9: No | HN9: No | HO9: SÃ­
A10: 8 | B10: 2025/07/08 11:36:12 AM CST | C10: PRUEBA PERLA VIRIDIANA GONZALEZ ESPARZA | D10: 33994 | E10: AdministraciÃ³n | F10: Auxiliar Administrativo | G10: Soltero | H10: Femenino | I10: Universidad | J10: Auxiliar Administrativo | K10: 6 a 9 aÃ±os | L10: mas de 3 aÃ±os | M10: Lunes a viernes | N10: 8 horas | O10: Publico | P10: No tengo | Q10: No aplica | R10: mas de 1 hora | S10: De $50 a $100 pesos | T10: Propia | U10: 1 a 2 veces a la semana | V10: 3 a 4 veces a la semana | W10: 5 o mas veces a la semana | X10: 3 a 4 veces a la semana | Y10: No, el ritmo de trabajo no me permite comprar y preparar mis alimentos | Z10: De 1 a 2 veces al aÃ±o | AA10: No tengo hijos | AB10: Sentado | AC10: SÃ­ | AD10: Aire acondicionado | AE10: Normal | AF10: No afecta | AG10: No se perciben olores | AH10: Adecuada a mis actividades | AI10: No le molestan estos aspectos | AJ10: No | AO10: Nunca | AP10: No | AU10: No | AX10: No | BC10: No | BD10: No | BE10: SÃ­ | BF10: No | BG10: No | BH10: No | BI10: No | BJ10: No | BK10: No | BS10: Alta | BT10: Suficiente | BU10: Objetivos que hay que alcanzar | BV10: Apresurado | BW10: Provoca problemas menores | BX10: SÃ­ | BY10: A menudo | BZ10: Algunas Veces | CA10: BUENA | CB10: BUENA | CC10: BUENA | CD10: No | CE10: No hay obstÃ¡culos que dificulten la comuniaciÃ³n | CF10: SÃ­ | CG10: 1 | CH10: SÃ­ | CI10: SÃ­ | CJ10: Indeterminado | CK10: De los mas importantes | CL10: FormaciÃ³n superior | CM10: Bastantes | CN10: No | CP10: SÃ­ | CQ10: Rara vez (una vez al mes o menos) | CR10: Si | CS10: Tequila, no he consumido durante mucho tiempo y aproximadamente 9 aÃ±os | CT10: Si | CU10: 1 o 2 dÃ­as a la semana | CV10: Diabetes;PresiÃ³n arterial alta | CW10: Ninguna | CY10: No aplica | CZ10: No consumo | DA10: NO | DB10: No | DC10: NO | DD10: No | DE10: NINGUNA | DF10: No | DG10: NINGUNA | DH10: Nunca | DI10: No aplica | DJ10: No | DK10: No | DL10: A veces | DM10: Nunca | DN10: Nunca | DO10: Nunca | DP10: Nunca | DQ10: Nunca | DR10: A veces | DS10: Nunca | DT10: A veces | DU10: A veces | DV10: Nunca | DW10: Nunca | DX10: Muchas veces | DY10: A veces | DZ10: A veces | EA10: Muchas veces | EB10: A veces | EC10: A veces | ED10: Nunca | EE10: Nunca | EF10: Nunca | EG10: Nunca | EH10: Nunca | EI10: Nunca | EJ10: Nunca | EK10: Nunca | EL10: Nunca | EM10: Nunca | EN10: A veces | EO10: Nunca | EP10: Nunca | EQ10: A veces | ER10: A veces | ES10: Nunca | ET10: A veces | EU10: A veces | EV10: A veces | EW10: A veces | EX10: A veces | EY10: Nunca | EZ10: Si | FA10: Ocasionalmente (algunas veces al mes) | FB10: No | FC10: Nunca | FD10: Si | FE10: A veces | FF10: Rara vez (una vez al mes o menos) | FG10: No | FH10: Nunca | FI10: Si | FJ10: SÃ­ | FK10: Regularmente (algunas veces a la semana) | FL10: A veces | FM10: Rara vez (una vez al mes o menos) | FN10: Si | FO10: A veces | FP10: Regularmente (algunas veces a la semana) | FQ10: No | FR10: Nunca | FS10: No | FT10: Mas de 4 horas | FU10: Menos de 30 minutos | FV10: Menos de 30 minutos | FW10: Nunca | FX10: Nunca | FY10: Nunca | FZ10: Entre 30 min y 2 horas | GA10: Nunca | GB10: Nunca | GC10: Nunca | GD10: Nunca | GE10: Nunca | GF10: Nunca | GG10: Nunca | GH10: Nunca | GI10: Nunca | GJ10: Nunca | GK10: Mas de 4 horas | GL10: Nunca | GM10: Nunca | GN10: Nunca | GO10: Nunca | GP10: Nunca | GQ10: No levanto peso | GR10: No levanto peso | GS10: Nunca | GT10: No levanto peso | GU10: No levanto peso | GV10: Nunca | GW10: No empujo | GX10: No | GY10: No | GZ10: No | HA10: No | HB10: No | HC10: No | HD10: No | HE10: No | HF10: No | HG10: No | HH10: No | HI10: No | HJ10: No | HK10: No | HL10: No | HM10: No | HN10: No | HO10: No
A11: 9

Sheet General
C1: =SUM(C4:C45) -> 49 | M1: =SUM(M4:M45) -> 80 | N1: =SUM(N4:N45) -> 19
C2: =+'Reporte Ind'!B1 -> 4
A3: Pregunta | B3: Respuesta | C3: Ponderación | D3: Respuestas
A4: 5 | B4: 7 | C4: =HLOOKUP(VLOOKUP($C$2,Respuestas!$A$2:$HO$11,VALUE(B4)),D4:L5,2,0) -> 1 | D4: Soltero | E4: Casado | F4: Viudo | G4: Divorciado
D5: 1 | E5: 1 | F5: 1 | G5: 1 | M5: =MAX(D5:L5) -> 1 | N5: =MIN(D5:L5) -> 1
A6: 6 | B6: 8 | C6: =HLOOKUP(VLOOKUP($C$2,Respuestas!$A$2:$HO$11,VALUE(B6)),D6:L7,2,0) -> 1 | D6: Masculino | E6: Femenino
D7: 2 | E7: 1 | M7: =MAX(D7:L7) -> 2 | N7: =MIN(D7:L7) -> 1
A8: 7 | B8: 9 | C8: =HLOOKUP(VLOOKUP($C$2,Respuestas!$A$2:$HO$11,VALUE(B8)),D8:L9,2,0) -> 2 | D8: Primaria | E8: Estudios técnicos | F8: Secundaria | G8: Preparatoria | H8: Universidad | I8: Posgrado
D9: 6 | E9: 5 | F9: 4 | G9: 3 | H9: 2 | I9: 1 | M9: =MAX(D9:L9) -> 6 | N9: =MIN(D9:L9) -> 1
A10: 8 | B10: 10 | C10: =HLOOKUP(VLOOKUP($C$2,Respuestas!$A$2:$HO$11,VALUE(B10)),D10:L11,2,0) -> 2 | D10: Obrero General | E10: Supervisor administrativo | F10: Oficial calificado | G10: Auxiliar administrativo | H10: Dirección | I10: Mandos Medios
D11: 5 | E11: 4 | F11: 3 | G11: 2 | H11: 1 | I11: 3 | M11: =MAX(D11:L11) -> 5 | N11: =MIN(D11:L11) -> 1
A12: 9 | B12: 11 | C12: =HLOOKUP(VLOOKUP($C$2,Respuestas!$A$2:$HO$11,VALUE(B12)),D12:L13,2,0) -> 4 | D12: menos de 1 año | E12: 1 a 3 años | F12: 3 a 6 años | G12: 6 a 9 años | H12: 9 a 12 años | I12: 12 a 15 años | J12: 15 a 18 años | K12: 18 a 21 años | L12: mas de 21 años
D13: 5 | E13: 5 | F13: 4 | G13: 4 | H13: 3 | I13: 3 | J13: 2 | K13: 2 | L13: 1 | M13: =MAX(D13:L13) -> 5 | N13: =MIN(D13:L13) -> 1
A14: 10 | B14: 12 | C14: =HLOOKUP(VLOOKUP($C$2,Respuestas!$A$2:$HO$11,VALUE(B14)),D14:L15,2,0) -> 1 | D14: menos de 1 año | E14: 1 a 2 años | F14: 2 a 3 años | G14: mas de 3 años
D15: 3 | E15: 3 | F15: 2 | G15: 1 | M15: =MAX(D15:L15) -> 3 | N15: =MIN(D15:L15) -> 1
A16: 11 | B16: 13 | C16: =HLOOKUP(VLOOKUP($C$2,Respuestas!$A$2:$HO$11,VALUE(B16)),D16:L17,2,0) -> 1 | D16: Lunes a viernes | E16: Lunes a sabado
D17: 1 | E17: 1 | M17: =MAX(D17:L17) -> 1 | N17: =MIN(D17:L17) -> 1
A18: 12 | B18: 14 | C18: =HLOOKUP(VLOOKUP($C$2,Respuestas!$A$2:$HO$11,VALUE(B18)),D18:L19,2,0) -> 1 | D18: menos de 7 horas | E18: 8 horas | F18: 9 horas | G18: 10 horas | H18: 11 horas | I18: 12 o más
D19: 1 | E19: 1 | F19: 1 | G19: 2 | H19: 2 | I19: 3 | M19: =MAX(D19:L19) -> 3 | N19: =MIN(D19:L19) -> 1
A20: 13 | B20: 15 | C20: =HLOOKUP(VLOOKUP($C$2,Respuestas!$A$2:$HO$11,VALUE(B20)),D20:L21,2,0) -> 3 | D20: Plataforma (Uber, DIDI u otros) | E20: Propio | F20: Público
D21: 1 | E21: 2 | F21: 3 | M21: =MAX(D21:L21) -> 3 | N21: =MIN(D21:L21) -> 1
A22: 14 | B22: 16 | C22: =HLOOKUP(VLOOKUP($C$2,Respuestas!$A$2:$HO$11,VALUE(B22)),D22:L23,2,0) -> 4 | D22: 1 | E22: 2 | F22: 3 | G22: más de 3 | H22: no tengo
D23: 3 | E23: 2 | F23: 1 | G23: 0 | H23: 4 | M23: =MAX(D23:L23) -> 4 | N23: =MIN(D23:L23) -> 0
A24: 15 | B24: 17 | C24: =HLOOKUP(VLOOKUP($C$2,Respuestas!$A$2:$HO$11,VALUE(B24)),D24:L25,2,0) -> 5 | D24: Menos de $300 pesos | E24: De $300 a $500 pesos | F24: De $500 a $1000 pesos | G24: Mas de $1500 pesos | H24: No aplica
D25: 1 | E25: 2 | F25: 3 | G25: 4 | H25: 5 | M25: =MAX(D25:L25) -> 5 | N25: =MIN(D25:L25) -> 1
A26: 16 | B26: 18 | C26: =HLOOKUP(VLOOKUP($C$2,Respuestas!$A$2:$HO$11,VALUE(B26)),D26:L27,2,0) -> 5 | D26: 0 a 15 minutos | E26: 16 a 30 minutos | F26: 31 a 45 minutos | G26: 45 a 60 minutos | H26: mas de 1 hora
D27: 1 | E27: 2 | F27: 3 | G27: 4 | H27: 5 | M27: =MAX(D27:L27) -> 5 | N27: =MIN(D27:L27) -> 1
A28: 17 | B28: 19 | C28: =HLOOKUP(VLOOKUP($C$2,Respuestas!$A$2:$HO$11,VALUE(B28)),D28:L29,2,0) -> 3 | D28: De $1 a $20 pesos | E28: De $20 a $50 pesos | F28: De $50 a $100 pesos | G28: Más de $100 pesos | H28: No aplica
D29: 1 | E29: 2 | F29: 3 | G29: 4 | H29: 0 | M29: =MAX(D29:L29) -> 4 | N29: =MIN(D29:L29) -> 0
A30: 18 | B30: 20 | C30: =HLOOKUP(VLOOKUP($C$2,Respuestas!$A$2:$HO$11,VALUE(B30)),D30:L31,2,0) -> 1 | D30: Propia | E30: Rentada | F30: Prestada
D31: 1 | E31: 2 | F31: 3 | M31: =MAX(D31:L31) -> 3 | N31: =MIN(D31:L31) -> 1
A32: 19 | B32: 21 | C32: =HLOOKUP(VLOOKUP($C$2,Respuestas!$A$2:$HO$11,VALUE(B32)),D32:L33,2,0) -> 3 | D32: No consumo | E32: Menos de 1 vez a la semana | F32: 1 a 2 veces a la semana | G32: 3 a 4 veces a la semana | H32: 5 o mas veces a la semana
D33: 5 | E33: 4 | F33: 3 | G33: 2 | H33: 1 | M33: =MAX(D33:L33) -> 5 | N33: =MIN(D33:L33) -> 1
A34: 19 | B34: 22 | C34: =HLOOKUP(VLOOKUP($C$2,Respuestas!$A$2:$HO$11,VALUE(B34)),D34:L35,2,0) -> 2 | D34: No consumo | E34: Menos de 1 vez a la semana | F34: 1 a 2 veces a la semana | G34: 3 a 4 veces a la semana | H34: 5 o mas veces a la semana
D35: 5 | E35: 4 | F35: 3 | G35: 2 | H35: 1 | M35: =MAX(D35:L35) -> 5 | N35: =MIN(D35:L35) -> 1
A36: 19 | B36: 23 | C36: =HLOOKUP(VLOOKUP($C$2,Respuestas!$A$2:$HO$11,VALUE(B36)),D36:L37,2,0) -> 1 | D36: No consumo | E36: Menos de 1 vez a la semana | F36: 1 a 2 veces a la semana | G36: 3 a 4 veces a la semana | H36: 5 o mas veces a la semana
D37: 5 | E37: 4 | F37: 3 | G37: 2 | H37: 1 | M37: =MAX(D37:L37) -> 5 | N37: =MIN(D37:L37) -> 1
A38: 19 | B38: 24 | C38: =HLOOKUP(VLOOKUP($C$2,Respuestas!$A$2:$HO$11,VALUE(B38)),D38:L39,2,0) -> 2 | D38: No consumo | E38: Menos de 1 vez a la semana | F38: 1 a 2 veces a la semana | G38: 3 a 4 veces a la semana | H38: 5 o mas veces a la semana
D39: 5 | E39: 4 | F39: 3 | G39: 2 | H39: 1 | M39: =MAX(D39:L39) -> 5 | N39: =MIN(D39:L39) -> 1
A40: 20 | B40: 25 | C40: =HLOOKUP(VLOOKUP($C$2,Respuestas!$A$2:$HO$11,VALUE(B40)),D40:L41,2,0) -> 2 | D40: No, economicamente no me es posible | E40: No, el ritmo de trabajo no me permite comprar y preparar mis alimentos | F40: Si, cuento con las recursos economicos y el tiempo para acceder a mis alimentos
...

Sheet Habitos
C1: =SUM(C4:C116) -> 12 | L1: =SUM(L4:L116) -> 4 | M1: =SUM(M4:M116) -> 44
C2: =+'Reporte Ind'!B1 -> 4
A3: Pregunta | B3: Respuesta | C3: Ponderación | D3: Respuestas
A4: 85 | B4: 92 | C4: =IFERROR(HLOOKUP(VLOOKUP($C$2,Respuestas!$A$2:$HO$11,VALUE(B4)),D4:K5,2,0),"") -> 1 | D4: Sí | E4: No
D5: 0 | E5: 1 | L5: =MIN(D5:K5) -> 0 | M5: =MAX(D5:K5) -> 1
A6: 86 | B6: 93 | C6: =IF(VLOOKUP($C$2,Respuestas!$A$2:$HO$11,VALUE(B6),0)=0, " ", VLOOKUP($C$2,Respuestas!$A$2:$HO$11,VALUE(B6),0)) | D6: Detalle…
L7: =MIN(D7:K7) -> 0 | M7: =MAX(D7:K7) -> 0
A8: 87 | B8: 94 | C8: =IFERROR(HLOOKUP(VLOOKUP($C$2,Respuestas!$A$2:$HO$11,VALUE(B8)),D8:K9,2,0),"") -> 2 | D8: Sí | E8: No
D9: 2 | E9: 1 | L9: =MIN(D9:K9) -> 1 | M9: =MAX(D9:K9) -> 2
A10: 88 | B10: 95 | C10: =IFERROR(HLOOKUP(VLOOKUP($C$2,Respuestas!$A$2:$HO$11,VALUE(B10)),D10:K11,2,0),"") -> 2 | D10: Nunca | E10: Rara vez (una vez al mes o menos) | F10: Ocasionalmente (algunas veces al mes) | G10: Regularmente (algunas veces a la semana) | H10: Frecuentemente (todos los días) | I10: No aplica
D11: 1 | E11: 2 | F11: 2 | G11: 3 | H11: 3 | I11: 0 | L11: =MIN(D11:K11) -> 0 | M11: =MAX(D11:K11) -> 3
A12: 89 | B12: 96 | C12: =IFERROR(HLOOKUP(VLOOKUP($C$2,Respuestas!$A$2:$HO$11,VALUE(B12)),D12:K13,2,0),"") -> 2 | D12: Si | E12: No
D13: 2 | E13: 1 | L13: =MIN(D13:K13) -> 1 | M13: =MAX(D13:K13) -> 2
A14: 90 | B14: 97 | C14: =IF(VLOOKUP($C$2,Respuestas!$A$2:$HO$11,VALUE(B14),0)=0, " ", VLOOKUP($C$2,Respuestas!$A$2:$HO$11,VALUE(B14),0)) -> Tequila, no he consumido durante mucho tiempo y aproximadamente 9 años | F14: Ninguno
L15: =MIN(D15:K15) -> 0 | M15: =MAX(D15:K15) -> 0
A16: 91 | B16: 98 | C16: =IFERROR(HLOOKUP(VLOOKUP($C$2,Respuestas!$A$2:$HO$11,VALUE(B16)),D16:K17,2,0),"") -> 1 | D16: Si | E16: No
D17: 1 | E17: 2 | L17: =MIN(D17:K17) -> 1 | M17: =MAX(D17:K17) -> 2
A18: 92 | B18: 99 | C18: =IFERROR(HLOOKUP(VLOOKUP($C$2,Respuestas!$A$2:$HO$11,VALUE(B18)),D18:K19,2,0),"") -> 2 | D18: No realizo | E18: 1 o 2 días a la semana | F18: 3 o 5 días a la semana | G18: Mas de 5 días a la semana
D19: 1 | E19: 2 | F19: 3 | G19: 4 | L19: =MIN(D19:K19) -> 1 | M19: =MAX(D19:K19) -> 4
A20: 93 | B20: 100 | C20: =IF(VLOOKUP($C$2,Respuestas!$A$2:$HO$11,VALUE(B20),0)=0, " ", VLOOKUP($C$2,Respuestas!$A$2:$HO$11,VALUE(B20),0)) -> Diabetes, Presión arterial alta | D20: Ninguna de las anteriores
C21: =IF(C20=D20,D21,(LEN(C20)-LEN(SUBSTITUTE(C20,",", ""))+1)) -> 2 | D21: 0 | L21: =MIN(D21:K21) -> 0 | M21: 9
A22: 94 | B22: 101 | C22: =IF(VLOOKUP($C$2,Respuestas!$A$2:$HO$11,VALUE(B22),0)=0, " ", VLOOKUP($C$2,Respuestas!$A$2:$HO$11,VALUE(B22),0)) -> Ninguna | D22: Ninguna
C23: =IF(C22=D22,D23,(LEN(C22)-LEN(SUBSTITUTE(C22,",", ""))+1))*2 -> 0 | D23: 0 | L23: =MIN(D23:K23) -> 0 | M23: 8
A24: 95 | B24: 102 | C24: =IF(VLOOKUP($C$2,Respuestas!$A$2:$HO$11,VALUE(B24),0)=0, " ", VLOOKUP($C$2,Respuestas!$A$2:$HO$11,VALUE(B24),0)) | D24: Otro….
L25: =MIN(D25:K25) -> 0 | M25: =MAX(D25:K25) -> 0
